Microsoft Windows [versão 10.0.22621.2428]
(c) Microsoft Corporation. Todos os direitos reservados.

C:\Users\milyb\Documents\PYTHON>python -m venv django1

C:\Users\milyb\Documents\PYTHON>django1\Scripts\activate

(django1) C:\Users\milyb\Documents\PYTHON>python
Python 3.8.2 (tags/v3.8.2:7b3ab59, Feb 25 2020, 23:03:10) [MSC v.1916 64 bit (AMD64)] on win32
Type "help", "copyright", "credits" or "license" for more information.
>>> quit()

(django1) C:\Users\milyb\Documents\PYTHON>pip install django
Collecting django
  Using cached https://files.pythonhosted.org/packages/8a/79/7f45e9c129c3cd8e4d54806649efeb1db9c223c54a1c54b30511d246bc60/Django-4.2.8-py3-none-any.whl
Collecting backports.zoneinfo; python_version < "3.9" (from django)
  Using cached https://files.pythonhosted.org/packages/78/cc/e27fd6493bbce8dbea7e6c1bc861fe3d3bc22c4f7c81f4c3befb8ff5bfaf/backports.zoneinfo-0.2.1-cp38-cp38-win_amd64.whl
Collecting asgiref<4,>=3.6.0 (from django)
  Using cached https://files.pythonhosted.org/packages/9b/80/b9051a4a07ad231558fcd8ffc89232711b4e618c15cb7a392a17384bbeef/asgiref-3.7.2-py3-none-any.whl
Collecting sqlparse>=0.3.1 (from django)
  Using cached https://files.pythonhosted.org/packages/98/5a/66d7c9305baa9f11857f247d4ba761402cea75db6058ff850ed7128957b7/sqlparse-0.4.4-py3-none-any.whl
Collecting tzdata; sys_platform == "win32" (from django)
  Using cached https://files.pythonhosted.org/packages/d5/fb/a79efcab32b8a1f1ddca7f35109a50e4a80d42ac1c9187ab46522b2407d7/tzdata-2023.3-py2.py3-none-any.whl
Collecting typing-extensions>=4; python_version < "3.11" (from asgiref<4,>=3.6.0->django)
  Using cached https://files.pythonhosted.org/packages/b7/f4/6a90020cd2d93349b442bfcb657d0dc91eee65491600b2cb1d388bc98e6b/typing_extensions-4.9.0-py3-none-any.whl
Installing collected packages: backports.zoneinfo, typing-extensions, asgiref, sqlparse, tzdata, django
Successfully installed asgiref-3.7.2 backports.zoneinfo-0.2.1 django-4.2.8 sqlparse-0.4.4 typing-extensions-4.9.0 tzdata-2023.3
WARNING: You are using pip version 19.2.3, however version 23.3.2 is available.
You should consider upgrading via the 'python -m pip install --upgrade pip' command.

(django1) C:\Users\milyb\Documents\PYTHON>pip freeze > requirements.txt

(django1) C:\Users\milyb\Documents\PYTHON>cd django1

(django1) C:\Users\milyb\Documents\PYTHON\django1>pip freeze > requirements.txt

(django1) C:\Users\milyb\Documents\PYTHON\django1>django-admin startproject django1 .

(django1) C:\Users\milyb\Documents\PYTHON\django1>django-admin startapp core

(django1) C:\Users\milyb\Documents\PYTHON\django1>dir
 O volume na unidade C é OS
 O Número de Série do Volume é DCDF-8226

 Pasta de C:\Users\milyb\Documents\PYTHON\django1

25/12/2023  20:14    <DIR>          .
25/12/2023  20:38    <DIR>          ..
25/12/2023  20:14    <DIR>          core
25/12/2023  19:51    <DIR>          django1
25/12/2023  19:32    <DIR>          Include
25/12/2023  19:32    <DIR>          Lib
25/12/2023  19:52               685 manage.py
25/12/2023  19:32                89 pyvenv.cfg
25/12/2023  19:38               117 requirements.txt
25/12/2023  19:35    <DIR>          Scripts
               3 arquivo(s)            891 bytes
               7 pasta(s)   103.347.691.520 bytes disponíveis

(django1) C:\Users\milyb\Documents\PYTHON\django1>python manage.py runserver
Watching for file changes with StatReloader
Performing system checks...

System check identified no issues (0 silenced).

You have 18 unapplied migration(s). Your project may not work properly until you apply the migrations for app(s): admin, auth, contenttypes, sessions.
Run 'python manage.py migrate' to apply them.
December 25, 2023 - 20:42:52
Django version 4.2.8, using settings 'django1.settings'
Starting development server at http://127.0.0.1:8000/
Quit the server with CTRL-BREAK.

[25/Dec/2023 20:43:17] "GET / HTTP/1.1" 200 10664
Not Found: /favicon.ico
[25/Dec/2023 20:43:17] "GET /favicon.ico HTTP/1.1" 404 2111
C:\Users\milyb\Documents\PYTHON\django1\django1\settings.py changed, reloading.
Watching for file changes with StatReloader
Performing system checks...

System check identified no issues (0 silenced).

You have 18 unapplied migration(s). Your project may not work properly until you apply the migrations for app(s): admin, auth, contenttypes, sessions.
Run 'python manage.py migrate' to apply them.
December 25, 2023 - 20:48:07
Django version 4.2.8, using settings 'django1.settings'
Starting development server at http://127.0.0.1:8000/
Quit the server with CTRL-BREAK.

[25/Dec/2023 20:48:15] "GET / HTTP/1.1" 200 10695

(django1) C:\Users\milyb\Documents\PYTHON\django1># https://docs.djangoproject.com/en/4.2/ref/settings/#databases
'#' não é reconhecido como um comando interno
ou externo, um programa operável ou um arquivo em lotes.

(django1) C:\Users\milyb\Documents\PYTHON\django1>python manage.py runserver
Watching for file changes with StatReloader
Performing system checks...

System check identified no issues (0 silenced).

You have 18 unapplied migration(s). Your project may not work properly until you apply the migrations for app(s): admin, auth, contenttypes, sessions.
Run 'python manage.py migrate' to apply them.
December 25, 2023 - 21:07:45
Django version 4.2.8, using settings 'django1.settings'
Starting development server at http://127.0.0.1:8000/
Quit the server with CTRL-BREAK.

[25/Dec/2023 21:07:51] "GET / HTTP/1.1" 200 10695
C:\Users\milyb\Documents\PYTHON\django1\django1\urls.py changed, reloading.
Watching for file changes with StatReloader
Performing system checks...

Exception in thread django-main-thread:
Traceback (most recent call last):
  File "C:\Program Files\Python38\lib\threading.py", line 932, in _bootstrap_inner
    self.run()
  File "C:\Program Files\Python38\lib\threading.py", line 870, in run
    self._target(*self._args, **self._kwargs)
  File "C:\Users\milyb\Documents\PYTHON\django1\lib\site-packages\django\utils\autoreload.py", line 64, in wrapper
    fn(*args, **kwargs)
  File "C:\Users\milyb\Documents\PYTHON\django1\lib\site-packages\django\core\management\commands\runserver.py", line 133, in inner_run
    self.check(display_num_errors=True)
  File "C:\Users\milyb\Documents\PYTHON\django1\lib\site-packages\django\core\management\base.py", line 485, in check
    all_issues = checks.run_checks(
  File "C:\Users\milyb\Documents\PYTHON\django1\lib\site-packages\django\core\checks\registry.py", line 88, in run_checks
    new_errors = check(app_configs=app_configs, databases=databases)
  File "C:\Users\milyb\Documents\PYTHON\django1\lib\site-packages\django\core\checks\urls.py", line 42, in check_url_namespaces_unique
    all_namespaces = _load_all_namespaces(resolver)
  File "C:\Users\milyb\Documents\PYTHON\django1\lib\site-packages\django\core\checks\urls.py", line 61, in _load_all_namespaces
    url_patterns = getattr(resolver, "url_patterns", [])
  File "C:\Users\milyb\Documents\PYTHON\django1\lib\site-packages\django\utils\functional.py", line 57, in __get__
    res = instance.__dict__[self.name] = self.func(instance)
  File "C:\Users\milyb\Documents\PYTHON\django1\lib\site-packages\django\urls\resolvers.py", line 715, in url_patterns
    patterns = getattr(self.urlconf_module, "urlpatterns", self.urlconf_module)
  File "C:\Users\milyb\Documents\PYTHON\django1\lib\site-packages\django\utils\functional.py", line 57, in __get__
    res = instance.__dict__[self.name] = self.func(instance)
  File "C:\Users\milyb\Documents\PYTHON\django1\lib\site-packages\django\urls\resolvers.py", line 708, in urlconf_module
    return import_module(self.urlconf_name)
  File "C:\Program Files\Python38\lib\importlib\__init__.py", line 127, in import_module
    return _bootstrap._gcd_import(name[level:], package, level)
  File "<frozen importlib._bootstrap>", line 1014, in _gcd_import
  File "<frozen importlib._bootstrap>", line 991, in _find_and_load
  File "<frozen importlib._bootstrap>", line 975, in _find_and_load_unlocked
  File "<frozen importlib._bootstrap>", line 671, in _load_unlocked
  File "<frozen importlib._bootstrap_external>", line 783, in exec_module
  File "<frozen importlib._bootstrap>", line 219, in _call_with_frames_removed
  File "C:\Users\milyb\Documents\PYTHON\django1\django1\urls.py", line 20, in <module>
    from core.views import idex,contato
ImportError: cannot import name 'idex' from 'core.views' (C:\Users\milyb\Documents\PYTHON\django1\core\views.py)
C:\Users\milyb\Documents\PYTHON\django1\django1\urls.py changed, reloading.
Watching for file changes with StatReloader
Performing system checks...

Exception in thread django-main-thread:
Traceback (most recent call last):
  File "C:\Program Files\Python38\lib\threading.py", line 932, in _bootstrap_inner
    self.run()
  File "C:\Program Files\Python38\lib\threading.py", line 870, in run
    self._target(*self._args, **self._kwargs)
  File "C:\Users\milyb\Documents\PYTHON\django1\lib\site-packages\django\utils\autoreload.py", line 64, in wrapper
    fn(*args, **kwargs)
  File "C:\Users\milyb\Documents\PYTHON\django1\lib\site-packages\django\core\management\commands\runserver.py", line 133, in inner_run
    self.check(display_num_errors=True)
  File "C:\Users\milyb\Documents\PYTHON\django1\lib\site-packages\django\core\management\base.py", line 485, in check
    all_issues = checks.run_checks(
  File "C:\Users\milyb\Documents\PYTHON\django1\lib\site-packages\django\core\checks\registry.py", line 88, in run_checks
    new_errors = check(app_configs=app_configs, databases=databases)
  File "C:\Users\milyb\Documents\PYTHON\django1\lib\site-packages\django\core\checks\urls.py", line 42, in check_url_namespaces_unique
    all_namespaces = _load_all_namespaces(resolver)
  File "C:\Users\milyb\Documents\PYTHON\django1\lib\site-packages\django\core\checks\urls.py", line 61, in _load_all_namespaces
    url_patterns = getattr(resolver, "url_patterns", [])
  File "C:\Users\milyb\Documents\PYTHON\django1\lib\site-packages\django\utils\functional.py", line 57, in __get__
    res = instance.__dict__[self.name] = self.func(instance)
  File "C:\Users\milyb\Documents\PYTHON\django1\lib\site-packages\django\urls\resolvers.py", line 715, in url_patterns
    patterns = getattr(self.urlconf_module, "urlpatterns", self.urlconf_module)
  File "C:\Users\milyb\Documents\PYTHON\django1\lib\site-packages\django\utils\functional.py", line 57, in __get__
    res = instance.__dict__[self.name] = self.func(instance)
  File "C:\Users\milyb\Documents\PYTHON\django1\lib\site-packages\django\urls\resolvers.py", line 708, in urlconf_module
    return import_module(self.urlconf_name)
  File "C:\Program Files\Python38\lib\importlib\__init__.py", line 127, in import_module
    return _bootstrap._gcd_import(name[level:], package, level)
  File "<frozen importlib._bootstrap>", line 1014, in _gcd_import
  File "<frozen importlib._bootstrap>", line 991, in _find_and_load
  File "<frozen importlib._bootstrap>", line 975, in _find_and_load_unlocked
  File "<frozen importlib._bootstrap>", line 671, in _load_unlocked
  File "<frozen importlib._bootstrap_external>", line 783, in exec_module
  File "<frozen importlib._bootstrap>", line 219, in _call_with_frames_removed
  File "C:\Users\milyb\Documents\PYTHON\django1\django1\urls.py", line 20, in <module>
    from core.views import idex,contato
ImportError: cannot import name 'idex' from 'core.views' (C:\Users\milyb\Documents\PYTHON\django1\core\views.py)
C:\Users\milyb\Documents\PYTHON\django1\django1\urls.py changed, reloading.
Watching for file changes with StatReloader
Performing system checks...

System check identified no issues (0 silenced).

You have 18 unapplied migration(s). Your project may not work properly until you apply the migrations for app(s): admin, auth, contenttypes, sessions.
Run 'python manage.py migrate' to apply them.
December 25, 2023 - 21:09:23
Django version 4.2.8, using settings 'django1.settings'
Starting development server at http://127.0.0.1:8000/
Quit the server with CTRL-BREAK.

Internal Server Error: /
Traceback (most recent call last):
  File "C:\Users\milyb\Documents\PYTHON\django1\lib\site-packages\django\core\handlers\exception.py", line 55, in inner
    response = get_response(request)
  File "C:\Users\milyb\Documents\PYTHON\django1\lib\site-packages\django\core\handlers\base.py", line 197, in _get_response
    response = wrapped_callback(request, *callback_args, **callback_kwargs)
  File "C:\Users\milyb\Documents\PYTHON\django1\core\views.py", line 4, in index
    return render(request,'index.html')
  File "C:\Users\milyb\Documents\PYTHON\django1\lib\site-packages\django\shortcuts.py", line 24, in render
    content = loader.render_to_string(template_name, context, request, using=using)
  File "C:\Users\milyb\Documents\PYTHON\django1\lib\site-packages\django\template\loader.py", line 61, in render_to_string
    template = get_template(template_name, using=using)
  File "C:\Users\milyb\Documents\PYTHON\django1\lib\site-packages\django\template\loader.py", line 19, in get_template
    raise TemplateDoesNotExist(template_name, chain=chain)
django.template.exceptions.TemplateDoesNotExist: index.html
[25/Dec/2023 21:09:50] "GET / HTTP/1.1" 500 75920
C:\Users\milyb\Documents\PYTHON\django1\django1\settings.py changed, reloading.
Traceback (most recent call last):
  File "manage.py", line 22, in <module>
    main()
  File "manage.py", line 18, in main
    execute_from_command_line(sys.argv)
  File "C:\Users\milyb\Documents\PYTHON\django1\lib\site-packages\django\core\management\__init__.py", line 442, in execute_from_command_line
    utility.execute()
  File "C:\Users\milyb\Documents\PYTHON\django1\lib\site-packages\django\core\management\__init__.py", line 382, in execute
    settings.INSTALLED_APPS
  File "C:\Users\milyb\Documents\PYTHON\django1\lib\site-packages\django\conf\__init__.py", line 102, in __getattr__
    self._setup(name)
  File "C:\Users\milyb\Documents\PYTHON\django1\lib\site-packages\django\conf\__init__.py", line 89, in _setup
    self._wrapped = Settings(settings_module)
  File "C:\Users\milyb\Documents\PYTHON\django1\lib\site-packages\django\conf\__init__.py", line 217, in __init__
    mod = importlib.import_module(self.SETTINGS_MODULE)
  File "C:\Program Files\Python38\lib\importlib\__init__.py", line 127, in import_module
    return _bootstrap._gcd_import(name[level:], package, level)
  File "<frozen importlib._bootstrap>", line 1014, in _gcd_import
  File "<frozen importlib._bootstrap>", line 991, in _find_and_load
  File "<frozen importlib._bootstrap>", line 975, in _find_and_load_unlocked
  File "<frozen importlib._bootstrap>", line 671, in _load_unlocked
  File "<frozen importlib._bootstrap_external>", line 783, in exec_module
  File "<frozen importlib._bootstrap>", line 219, in _call_with_frames_removed
  File "C:\Users\milyb\Documents\PYTHON\django1\django1\settings.py", line 26, in <module>
    DEBUG = false
NameError: name 'false' is not defined

(django1) C:\Users\milyb\Documents\PYTHON\django1>python manage.py runserver
Watching for file changes with StatReloader
Performing system checks...

System check identified no issues (0 silenced).

You have 18 unapplied migration(s). Your project may not work properly until you apply the migrations for app(s): admin, auth, contenttypes, sessions.
Run 'python manage.py migrate' to apply them.
December 25, 2023 - 21:13:08
Django version 4.2.8, using settings 'django1.settings'
Starting development server at http://127.0.0.1:8000/
Quit the server with CTRL-BREAK.

Internal Server Error: /
Traceback (most recent call last):
  File "C:\Users\milyb\Documents\PYTHON\django1\lib\site-packages\django\core\handlers\exception.py", line 55, in inner
    response = get_response(request)
  File "C:\Users\milyb\Documents\PYTHON\django1\lib\site-packages\django\core\handlers\base.py", line 197, in _get_response
    response = wrapped_callback(request, *callback_args, **callback_kwargs)
  File "C:\Users\milyb\Documents\PYTHON\django1\core\views.py", line 4, in index
    return render(request,'index.html')
  File "C:\Users\milyb\Documents\PYTHON\django1\lib\site-packages\django\shortcuts.py", line 24, in render
    content = loader.render_to_string(template_name, context, request, using=using)
  File "C:\Users\milyb\Documents\PYTHON\django1\lib\site-packages\django\template\loader.py", line 61, in render_to_string
    template = get_template(template_name, using=using)
  File "C:\Users\milyb\Documents\PYTHON\django1\lib\site-packages\django\template\loader.py", line 19, in get_template
    raise TemplateDoesNotExist(template_name, chain=chain)
django.template.exceptions.TemplateDoesNotExist: index.html
[25/Dec/2023 21:13:17] "GET / HTTP/1.1" 500 75920
[25/Dec/2023 21:15:34] "GET /admin HTTP/1.1" 301 0
[25/Dec/2023 21:15:35] "GET /admin/ HTTP/1.1" 302 0
[25/Dec/2023 21:15:35] "GET /admin/login/?next=/admin/ HTTP/1.1" 200 4209
[25/Dec/2023 21:15:35] "GET /static/admin/css/base.css HTTP/1.1" 200 21310
[25/Dec/2023 21:15:35] "GET /static/admin/css/dark_mode.css HTTP/1.1" 200 2929
[25/Dec/2023 21:15:35] "GET /static/admin/css/nav_sidebar.css HTTP/1.1" 200 2694
[25/Dec/2023 21:15:35] "GET /static/admin/css/login.css HTTP/1.1" 200 958
[25/Dec/2023 21:15:35] "GET /static/admin/css/responsive.css HTTP/1.1" 200 18559
[25/Dec/2023 21:15:35] "GET /static/admin/js/theme.js HTTP/1.1" 200 1943
[25/Dec/2023 21:15:35] "GET /static/admin/js/nav_sidebar.js HTTP/1.1" 200 3063
Internal Server Error: /
Traceback (most recent call last):
  File "C:\Users\milyb\Documents\PYTHON\django1\lib\site-packages\django\core\handlers\exception.py", line 55, in inner
    response = get_response(request)
  File "C:\Users\milyb\Documents\PYTHON\django1\lib\site-packages\django\core\handlers\base.py", line 197, in _get_response
    response = wrapped_callback(request, *callback_args, **callback_kwargs)
  File "C:\Users\milyb\Documents\PYTHON\django1\core\views.py", line 4, in index
    return render(request,'index.html')
  File "C:\Users\milyb\Documents\PYTHON\django1\lib\site-packages\django\shortcuts.py", line 24, in render
    content = loader.render_to_string(template_name, context, request, using=using)
  File "C:\Users\milyb\Documents\PYTHON\django1\lib\site-packages\django\template\loader.py", line 61, in render_to_string
    template = get_template(template_name, using=using)
  File "C:\Users\milyb\Documents\PYTHON\django1\lib\site-packages\django\template\loader.py", line 19, in get_template
    raise TemplateDoesNotExist(template_name, chain=chain)
django.template.exceptions.TemplateDoesNotExist: index.html
[25/Dec/2023 21:15:59] "GET / HTTP/1.1" 500 76384
C:\Users\milyb\Documents\PYTHON\django1\django1\urls.py changed, reloading.
Watching for file changes with StatReloader
Performing system checks...

Exception in thread django-main-thread:
Traceback (most recent call last):
  File "C:\Program Files\Python38\lib\threading.py", line 932, in _bootstrap_inner
    self.run()
  File "C:\Program Files\Python38\lib\threading.py", line 870, in run
    self._target(*self._args, **self._kwargs)
  File "C:\Users\milyb\Documents\PYTHON\django1\lib\site-packages\django\utils\autoreload.py", line 64, in wrapper
    fn(*args, **kwargs)
  File "C:\Users\milyb\Documents\PYTHON\django1\lib\site-packages\django\core\management\commands\runserver.py", line 133, in inner_run
    self.check(display_num_errors=True)
  File "C:\Users\milyb\Documents\PYTHON\django1\lib\site-packages\django\core\management\base.py", line 485, in check
    all_issues = checks.run_checks(
  File "C:\Users\milyb\Documents\PYTHON\django1\lib\site-packages\django\core\checks\registry.py", line 88, in run_checks
    new_errors = check(app_configs=app_configs, databases=databases)
  File "C:\Users\milyb\Documents\PYTHON\django1\lib\site-packages\django\core\checks\urls.py", line 42, in check_url_namespaces_unique
    all_namespaces = _load_all_namespaces(resolver)
  File "C:\Users\milyb\Documents\PYTHON\django1\lib\site-packages\django\core\checks\urls.py", line 61, in _load_all_namespaces
    url_patterns = getattr(resolver, "url_patterns", [])
  File "C:\Users\milyb\Documents\PYTHON\django1\lib\site-packages\django\utils\functional.py", line 57, in __get__
    res = instance.__dict__[self.name] = self.func(instance)
  File "C:\Users\milyb\Documents\PYTHON\django1\lib\site-packages\django\urls\resolvers.py", line 715, in url_patterns
    patterns = getattr(self.urlconf_module, "urlpatterns", self.urlconf_module)
  File "C:\Users\milyb\Documents\PYTHON\django1\lib\site-packages\django\utils\functional.py", line 57, in __get__
    res = instance.__dict__[self.name] = self.func(instance)
  File "C:\Users\milyb\Documents\PYTHON\django1\lib\site-packages\django\urls\resolvers.py", line 708, in urlconf_module
    return import_module(self.urlconf_name)
  File "C:\Program Files\Python38\lib\importlib\__init__.py", line 127, in import_module
    return _bootstrap._gcd_import(name[level:], package, level)
  File "<frozen importlib._bootstrap>", line 1014, in _gcd_import
  File "<frozen importlib._bootstrap>", line 991, in _find_and_load
  File "<frozen importlib._bootstrap>", line 975, in _find_and_load_unlocked
  File "<frozen importlib._bootstrap>", line 671, in _load_unlocked
  File "<frozen importlib._bootstrap_external>", line 783, in exec_module
  File "<frozen importlib._bootstrap>", line 219, in _call_with_frames_removed
  File "C:\Users\milyb\Documents\PYTHON\django1\django1\urls.py", line 24, in <module>
    path('',include('core.urls')),
NameError: name 'include' is not defined

(django1) C:\Users\milyb\Documents\PYTHON\django1>python manage.py runserver
Watching for file changes with StatReloader
Performing system checks...

System check identified no issues (0 silenced).

You have 18 unapplied migration(s). Your project may not work properly until you apply the migrations for app(s): admin, auth, contenttypes, sessions.
Run 'python manage.py migrate' to apply them.
December 25, 2023 - 21:25:30
Django version 4.2.8, using settings 'django1.settings'
Starting development server at http://127.0.0.1:8000/
Quit the server with CTRL-BREAK.

Internal Server Error: /
Traceback (most recent call last):
  File "C:\Users\milyb\Documents\PYTHON\django1\lib\site-packages\django\core\handlers\exception.py", line 55, in inner
    response = get_response(request)
  File "C:\Users\milyb\Documents\PYTHON\django1\lib\site-packages\django\core\handlers\base.py", line 197, in _get_response
    response = wrapped_callback(request, *callback_args, **callback_kwargs)
  File "C:\Users\milyb\Documents\PYTHON\django1\core\views.py", line 4, in index
    return render(request,'index.html')
  File "C:\Users\milyb\Documents\PYTHON\django1\lib\site-packages\django\shortcuts.py", line 24, in render
    content = loader.render_to_string(template_name, context, request, using=using)
  File "C:\Users\milyb\Documents\PYTHON\django1\lib\site-packages\django\template\loader.py", line 61, in render_to_string
    template = get_template(template_name, using=using)
  File "C:\Users\milyb\Documents\PYTHON\django1\lib\site-packages\django\template\loader.py", line 19, in get_template
    raise TemplateDoesNotExist(template_name, chain=chain)
django.template.exceptions.TemplateDoesNotExist: index.html
[25/Dec/2023 21:25:35] "GET / HTTP/1.1" 500 76521
Internal Server Error: /
Traceback (most recent call last):
  File "C:\Users\milyb\Documents\PYTHON\django1\lib\site-packages\django\core\handlers\exception.py", line 55, in inner
    response = get_response(request)
  File "C:\Users\milyb\Documents\PYTHON\django1\lib\site-packages\django\core\handlers\base.py", line 197, in _get_response
    response = wrapped_callback(request, *callback_args, **callback_kwargs)
  File "C:\Users\milyb\Documents\PYTHON\django1\core\views.py", line 4, in index
    return render(request,'index.html')
  File "C:\Users\milyb\Documents\PYTHON\django1\lib\site-packages\django\shortcuts.py", line 24, in render
    content = loader.render_to_string(template_name, context, request, using=using)
  File "C:\Users\milyb\Documents\PYTHON\django1\lib\site-packages\django\template\loader.py", line 61, in render_to_string
    template = get_template(template_name, using=using)
  File "C:\Users\milyb\Documents\PYTHON\django1\lib\site-packages\django\template\loader.py", line 19, in get_template
    raise TemplateDoesNotExist(template_name, chain=chain)
django.template.exceptions.TemplateDoesNotExist: index.html
[25/Dec/2023 21:25:38] "GET / HTTP/1.1" 500 76521

(django1) C:\Users\milyb\Documents\PYTHON\django1>python manage.py runserver
Watching for file changes with StatReloader
Performing system checks...

System check identified no issues (0 silenced).

You have 18 unapplied migration(s). Your project may not work properly until you apply the migrations for app(s): admin, auth, contenttypes, sessions.
Run 'python manage.py migrate' to apply them.
December 25, 2023 - 21:36:17
Django version 4.2.8, using settings 'django1.settings'
Starting development server at http://127.0.0.1:8000/
Quit the server with CTRL-BREAK.

[25/Dec/2023 21:36:24] "GET / HTTP/1.1" 200 216
[25/Dec/2023 21:36:33] "GET /contato HTTP/1.1" 200 1018
[25/Dec/2023 21:38:40] "GET /contato HTTP/1.1" 200 1391
[25/Dec/2023 21:38:44] "GET /contato? HTTP/1.1" 200 1391
[25/Dec/2023 21:39:59] "GET /contato? HTTP/1.1" 200 1418
[25/Dec/2023 21:41:00] "GET / HTTP/1.1" 200 221
